Workbook

Sheet Control Panel
A1: Three Statement Model - Control Panel
A3: Scenario | B3: Base
A5: Revenue Growth (FY2026E) | B5: =INDEX(Assumptions!$B$5:$F$7,MATCH(B3,Assumptions!$A$5:$A$7,0),1) -> 0
A6: EBITDA Margin (FY2026E) | B6: =INDEX(Assumptions!$B$11:$F$13,MATCH(B3,Assumptions!$A$11:$A$13,0),1) -> 0
A7: Capex % Revenue (FY2026E) | B7: =INDEX(Assumptions!$B$17:$F$19,MATCH(B3,Assumptions!$A$17:$A$19,0),1) -> 0
A8: Receivables Days | B8: =Assumptions!B23 -> 0
A9: Inventory Days | B9: =Assumptions!B24 -> 0
A10: Payables Days | B10: =Assumptions!B25 -> 0
A11: Tax Rate | B11: =Assumptions!B26 -> 0
A12: Interest Rate | B12: =Assumptions!B27 -> 0
A13: Minimum Cash % Revenue | B13: =Assumptions!B28 -> 0
A15: Model checks
A16: Latest Balance Check (FY2030E) | B16: ='Projection Model'!F28 -> 0

Sheet Historical Financials
A1: Historical Financials (INR bn)
B3: FY2023A | C3: FY2024A | D3: FY2025A
A4: Income Statement
A5: Revenue | B5: 974864 | C5: 1000122 | D5: 1071174
A6: COGS | B6: 601959 | C6: 598751 | D6: 645132
A7: Gross Profit | B7: 372905 | C7: 401371 | D7: 426042
A8: Operating Expenses | B8: 147190 | C8: 153488 | D8: 169560
A9: EBITDA | B9: 225715 | C9: 247883 | D9: 256482
A10: Depreciation | B10: 40303 | C10: 50832 | D10: 53136
A11: EBIT | B11: 185412 | C11: 197051 | D11: 203346
A12: Interest | B12: 19571 | C12: 23118 | D12: 24269
A13: Balance Sheet | B13: 20376 | C13: 25707 | D13: 25230
A14: Cash | B14: 68664 | C14: 97225 | D14: 106502
A15: Accounts Receivable | B15: 28448 | C15: 31628 | D15: 42121
A16: Inventory | B16: 140008 | C16: 152770 | D16: 146062
... A22: Total Liabilities + Equity | B22: 1607431 | C22: 1755986 | D22: 1950121

Sheet Assumptions
A1: Assumptions (Scenario-Driven)
A3: Revenue Growth
A4: Scenario | B4: FY2026E | C4: FY2027E | D4: FY2028E | E4: FY2029E | F4: FY2030E
A5: Base | B5: 0.09 | C5: 0.085 | D5: 0.08 | E5: 0.075 | F5: 0.07
A6: Bull | B6: 0.12 | C6: 0.11 | D6: 0.1 | E6: 0.095 | F6: 0.09
A7: Bear | B7: 0.05 | C7: 0.045 | D7: 0.04 | E7: 0.04 | F7: 0.035
A9: EBITDA Margin
A10: Scenario | B10: FY2026E | C10: FY2027E | D10: FY2028E | E10: FY2029E | F10: FY2030E
A11: Base | B11: 0.27 | C11: 0.272 | D11: 0.275 | E11: 0.277 | F11: 0.28
A12: Bull | B12: 0.29 | C12: 0.292 | D12: 0.295 | E12: 0.297 | F12: 0.3
A13: Bear | B13: 0.24 | C13: 0.238 | D13: 0.235 | E13: 0.233 | F13: 0.23
A15: Capex % Revenue
A16: Scenario | B16: FY2026E | C16: FY2027E | D16: FY2028E | E16: FY2029E | F16: FY2030E
A17: Base | B17: 0.11 | C17: 0.108 | D17: 0.105 | E17: 0.102 | F17: 0.1
A18: Bull | B18: 0.125 | C18: 0.122 | D18: 0.12 | E18: 0.118 | F18: 0.115
A19: Bear | B19: 0.09 | C19: 0.088 | D19: 0.085 | E19: 0.082 | F19: 0.08
A21: Global Assumptions
A22: Metric | B22: FY2026E | C22: FY2027E | D22: FY2028E | E22: FY2029E | F22: FY2030E
A23: AR Days | B23: 50 | C23: 50 | D23: 50 | E23: 50 | F23: 50
A24: Inventory Days | B24: 47 | C24: 47 | D24: 47 | E24: 47 | F24: 47
A25: AP Days | B25: 42 | C25: 42 | D25: 42 | E25: 42 | F25: 42
A26: Tax Rate | B26: 0.25 | C26: 0.25 | D26: 0.25 | E26: 0.25 | F26: 0.25
A27: Interest Rate | B27: 0.095 | C27: 0.095 | D27: 0.095 | E27: 0.095 | F27: 0.095
A28: Minimum Cash % Revenue | B28: 0.03 | C28: 0.03 | D28: 0.03 | E28: 0.03 | F28: 0.03
A29: Depreciation % Opening PPE | B29: 0.09 | C29: 0.09 | D29: 0.09 | E29: 0.09 | F29: 0.09
A30: Operating Expenses % Revenue | B30: 0.065 | C30: 0.064 | D30: 0.063 | E30: 0.062 | F30: 0.061
A31: Other Assets % Revenue | B31: 0.907 | C31: 0.907 | D31: 0.907 | E31: 0.907 | F31: 0.907
A32: Other Liabilities % Revenue | B32: 0.379 | C32: 0.379 | D32: 0.379 | E32: 0.379 | F32: 0.379

Sheet Working Capital Schedule
A1: Working Capital Schedule
A3: Line Item | B3: FY2026E | C3: FY2027E | D3: FY2028E | E3: FY2029E | F3: FY2030E
A4: Revenue | B4: ='Projection Model'!B5 -> 0 | C4: ='Projection Model'!C5 -> 0 | D4: ='Projection Model'!D5 -> 0 | E4: ='Projection Model'!E5 -> 0 | F4: ='Projection Model'!F5 -> 0
A5: COGS | B5: ='Projection Model'!B6 -> 0 | C5: ='Projection Model'!C6 -> 0 | D5: ='Projection Model'!D6 -> 0 | E5: ='Projection Model'!E6 -> 0 | F5: ='Projection Model'!F6 -> 0
A6: AR Days | B6: =INDEX(Assumptions!$B$23:$F$23,1,1) -> 0 | C6: =INDEX(Assumptions!$B$23:$F$23,1,2) -> 0 | D6: =INDEX(Assumptions!$B$23:$F$23,1,3) -> 0 | E6: =INDEX(Assumptions!$B$23:$F$23,1,4) -> 0 | F6: =INDEX(Assumptions!$B$23:$F$23,1,5) -> 0
A7: Inventory Days | B7: =INDEX(Assumptions!$B$24:$F$24,1,1) -> 0 | C7: =INDEX(Assumptions!$B$24:$F$24,1,2) -> 0 | D7: =INDEX(Assumptions!$B$24:$F$24,1,3) -> 0 | E7: =INDEX(Assumptions!$B$24:$F$24,1,4) -> 0 | F7: =INDEX(Assumptions!$B$24:$F$24,1,5) -> 0
A8: AP Days | B8: =INDEX(Assumptions!$B$25:$F$25,1,1) -> 0 | C8: =INDEX(Assumptions!$B$25:$F$25,1,2) -> 0 | D8: =INDEX(Assumptions!$B$25:$F$25,1,3) -> 0 | E8: =INDEX(Assumptions!$B$25:$F$25,1,4) -> 0 | F8: =INDEX(Assumptions!$B$25:$F$25,1,5) -> 0
A9: Accounts Receivable | B9: =B4*B6/365 -> 0 | C9: =C4*C6/365 -> 0 | D9: =D4*D6/365 -> 0 | E9: =E4*E6/365 -> 0 | F9: =F4*F6/365 -> 0
A10: Inventory | B10: =B5*B7/365 -> 0 | C10: =C5*C7/365 -> 0 | D10: =D5*D7/365 -> 0 | E10: =E5*E7/365 -> 0 | F10: =F5*F7/365 -> 0
A11: Accounts Payable | B11: =B5*B8/365 -> 0 | C11: =C5*C8/365 -> 0 | D11: =D5*D8/365 -> 0 | E11: =E5*E8/365 -> 0 | F11: =F5*F8/365 -> 0
A12: Net Working Capital | B12: =B9+B10-B11 -> 0 | C12: =C9+C10-C11 -> 0 | D12: =D9+D10-D11 -> 0 | E12: =E9+E10-E11 -> 0 | F12: =F9+F10-F11 -> 0
A13: Change in NWC | B13: =B12-('Historical Financials'!D15+'Historical Financials'!D16-'Historical Financials'!D19) -> 0 | C13: =C12-B12 -> 0 | D13: =D12-C12 -> 0 | E13: =E12-D12 -> 0 | F13: =F12-E12 -> 0

Sheet PPE Schedule
A1: PPE Roll-Forward Schedule
A3: Line Item | B3: FY2026E | C3: FY2027E | D3: FY2028E | E3: FY2029E | F3: FY2030E
A4: Opening PPE | B4: ='Historical Financials'!D17 -> 0 | C4: =B9 -> 0 | D4: =C9 -> 0 | E4: =D9 -> 0 | F4: =E9 -> 0
A5: Capex % Revenue | B5: =INDEX(Assumptions!$B$17:$F$19,MATCH('Control Panel'!$B$3,Assumptions!$A$5:$A$7,0),1) -> 0 | C5: =INDEX(Assumptions!$B$17:$F$19,MATCH('Control Panel'!$B$3,Assumptions!$A$5:$A$7,0),2) -> 0 | D5: =INDEX(Assumptions!$B$17:$F$19,MATCH('Control Panel'!$B$3,Assumptions!$A$5:$A$7,0),3) -> 0 | E5: =INDEX(Assumptions!$B$17:$F$19,MATCH('Control Panel'!$B$3,Assumptions!$A$5:$A$7,0),4) -> 0 | F5: =INDEX(Assumptions!$B$17:$F$19,MATCH('Control Panel'!$B$3,Assumptions!$A$5:$A$7,0),5) -> 0
A6: Capex | B6: ='Projection Model'!B5*B5 -> 0 | C6: ='Projection Model'!C5*C5 -> 0 | D6: ='Projection Model'!D5*D5 -> 0 | E6: ='Projection Model'!E5*E5 -> 0 | F6: ='Projection Model'!F5*F5 -> 0
A7: Depreciation % Opening PPE | B7: =INDEX(Assumptions!$B$29:$F$29,1,1) -> 0 | C7: =INDEX(Assumptions!$B$29:$F$29,1,2) -> 0 | D7: =INDEX(Assumptions!$B$29:$F$29,1,3) -> 0 | E7: =INDEX(Assumptions!$B$29:$F$29,1,4) -> 0 | F7: =INDEX(Assumptions!$B$29:$F$29,1,5) -> 0
A8: Depreciation | B8: =B4*B7 -> 0 | C8: =C4*C7 -> 0 | D8: =D4*D7 -> 0 | E8: =E4*E7 -> 0 | F8: =F4*F7 -> 0
A9: Closing PPE | B9: =B4+B6-B8 -> 0 | C9: =C4+C6-C8 -> 0 | D9: =D4+D6-D8 -> 0 | E9: =E4+E6-E8 -> 0 | F9: =F4+F6-F8 -> 0

Sheet Debt Schedule
A1: Debt Schedule
A3: Line Item | B3: FY2026E | C3: FY2027E | D3: FY2028E | E3: FY2029E | F3: FY2030E
A4: Opening Debt | B4: ='Historical Financials'!D20 -> 0 | C4: =B11 -> 0 | D4: =C11 -> 0 | E4: =D11 -> 0 | F4: =E11 -> 0
A5: Interest Rate | B5: =INDEX(Assumptions!$B$27:$F$27,1,1) -> 0 | C5: =INDEX(Assumptions!$B$27:$F$27,1,2) -> 0 | D5: =INDEX(Assumptions!$B$27:$F$27,1,3) -> 0 | E5: =INDEX(Assumptions!$B$27:$F$27,1,4) -> 0 | F5: =INDEX(Assumptions!$B$27:$F$27,1,5) -> 0
A6: Interest Expense | B6: =B4*B5 -> 0 | C6: =C4*C5 -> 0 | D6: =D4*D5 -> 0 | E6: =E4*E5 -> 0 | F6: =F4*F5 -> 0
A7: Beginning Cash | B7: ='Projection Model'!B39 -> 0 | C7: ='Projection Model'!C39 -> 0 | D7: ='Projection Model'!D39 -> 0 | E7: ='Projection Model'!E39 -> 0 | F7: ='Projection Model'!F39 -> 0
A8: Pre-Financing Cash | B8: =B7+'Projection Model'!B33+'Projection Model'!B35 -> 0 | C8: =C7+'Projection Model'!C33+'Projection Model'!C35 -> 0 | D8: =D7+'Projection Model'!D33+'Projection Model'!D35 -> 0 | E8: =E7+'Projection Model'!E33+'Projection Model'!E35 -> 0 | F8: =F7+'Projection Model'!F33+'Projection Model'!F35 -> 0
A9: Minimum Cash Target | B9: ='Projection Model'!B5*INDEX(Assumptions!$B$28:$F$28,1,1) -> 0 | C9: ='Projection Model'!C5*INDEX(Assumptions!$B$28:$F$28,1,2) -> 0 | D9: ='Projection Model'!D5*INDEX(Assumptions!$B$28:$F$28,1,3) -> 0 | E9: ='Projection Model'!E5*INDEX(Assumptions!$B$28:$F$28,1,4) -> 0 | F9: ='Projection Model'!F5*INDEX(Assumptions!$B$28:$F$28,1,5) -> 0
A10: Debt Draw / (Repay) | B10: =MAX(0,B9-B8)-MIN(B4,MAX(0,B8-B9)) -> 0 | C10: =MAX(0,C9-C8)-MIN(C4,MAX(0,C8-C9)) -> 0 | D10: =MAX(0,D9-D8)-MIN(D4,MAX(0,D8-D9)) -> 0 | E10: =MAX(0,E9-E8)-MIN(E4,MAX(0,E8-E9)) -> 0 | F10: =MAX(0,F9-F8)-MIN(F4,MAX(0,F8-F9)) -> 0
A11: Closing Debt | B11: =B4+B10 -> 0 | C11: =C4+C10 -> 0 | D11: =D4+D10 -> 0 | E11: =E4+E10 -> 0 | F11: =F4+F10 -> 0

Sheet Projection Model
A1: Integrated Projection Model (5-Year Forecast)
A2: Selected Scenario | B2: ='Control Panel'!B3 -> 0
A3: Line Item | B3: FY2026E | C3: FY2027E | D3: FY2028E | E3: FY2029E | F3: FY2030E
A4: Income Statement
A5: Revenue | B5: ='Historical Financials'!D5*(1+INDEX(Assumptions!$B$5:$F$7,MATCH('Control Panel'!$B$3,Assumptions!$A$5:$A$7,0),1)) -> 0 | C5: =B5*(1+INDEX(Assumptions!$B$5:$F$7,MATCH('Control Panel'!$B$3,Assumptions!$A$5:$A$7,0),2)) -> 0 | D5: =C5*(1+INDEX(Assumptions!$B$5:$F$7,MATCH('Control Panel'!$B$3,Assumptions!$A$5:$A$7,0),3)) -> 0 | E5: =D5*(1+INDEX(Assumptions!$B$5:$F$7,MATCH('Control Panel'!$B$3,Assumptions!$A$5:$A$7,0),4)) -> 0 | F5: =E5*(1+INDEX(Assumptions!$B$5:$F$7,MATCH('Control Panel'!$B$3,Assumptions!$A$5:$A$7,0),5)) -> 0
A6: COGS | B6: =B5-B8-B9 -> 0 | C6: =C5-C8-C9 -> 0 | D6: =D5-D8-D9 -> 0 | E6: =E5-E8-E9 -> 0 | F6: =F5-F8-F9 -> 0
A7: Gross Profit | B7: =B5-B6 -> 0 | C7: =C5-C6 -> 0 | D7: =D5-D6 -> 0 | E7: =E5-E6 -> 0 | F7: =F5-F6 -> 0
A8: Operating Expenses | B8: =B5*INDEX(Assumptions!$B$30:$F$30,1,1) -> 0 | C8: =C5*INDEX(Assumptions!$B$30:$F$30,1,2) -> 0 | D8: =D5*INDEX(Assumptions!$B$30:$F$30,1,3) -> 0 | E8: =E5*INDEX(Assumptions!$B$30:$F$30,1,4) -> 0 | F8: =F5*INDEX(Assumptions!$B$30:$F$30,1,5) -> 0
A9: EBITDA | B9: =B5*INDEX(Assumptions!$B$11:$F$13,MATCH('Control Panel'!$B$3,Assumptions!$A$5:$A$7,0),1) -> 0 | C9: =C5*INDEX(Assumptions!$B$11:$F$13,MATCH('Control Panel'!$B$3,Assumptions!$A$5:$A$7,0),2) -> 0 | D9: =D5*INDEX(Assumptions!$B$11:$F$13,MATCH('Control Panel'!$B$3,Assumptions!$A$5:$A$7,0),3) -> 0 | E9: =E5*INDEX(Assumptions!$B$11:$F$13,MATCH('Control Panel'!$B$3,Assumptions!$A$5:$A$7,0),4) -> 0 | F9: =F5*INDEX(Assumptions!$B$11:$F$13,MATCH('Control Panel'!$B$3,Assumptions!$A$5:$A$7,0),5) -> 0
A10: Depreciation | B10: ='PPE Schedule'!B8 -> 0 | C10: ='PPE Schedule'!C8 -> 0 | D10: ='PPE Schedule'!D8 -> 0 | E10: ='PPE Schedule'!E8 -> 0 | F10: ='PPE Schedule'!F8 -> 0
A11: EBIT | B11: =B9-B10 -> 0 | C11: =C9-C10 -> 0 | D11: =D9-D10 -> 0 | E11: =E9-E10 -> 0 | F11: =F9-F10 -> 0
A12: Interest | B12: ='Debt Schedule'!B6 -> 0 | C12: ='Debt Schedule'!C6 -> 0 | D12: ='Debt Schedule'!D6 -> 0 | E12: ='Debt Schedule'!E6 -> 0 | F12: ='Debt Schedule'!F6 -> 0
A13: EBT | B13: =B11-B12 -> 0 | C13: =C11-C12 -> 0 | D13: =D11-D12 -> 0 | E13: =E11-E12 -> 0 | F13: =F11-F12 -> 0
A14: Tax | B14: =MAX(0,B13*INDEX(Assumptions!$B$26:$F$26,1,1)) -> 0 | C14: =MAX(0,C13*INDEX(Assumptions!$B$26:$F$26,1,2)) -> 0 | D14: =MAX(0,D13*INDEX(Assumptions!$B$26:$F$26,1,3)) -> 0 | E14: =MAX(0,E13*INDEX(Assumptions!$B$26:$F$26,1,4)) -> 0 | F14: =MAX(0,F13*INDEX(Assumptions!$B$26:$F$26,1,5)) -> 0
A15: Net Income | B15: =B13-B14 -> 0 | C15: =C13-C14 -> 0 | D15: =D13-D14 -> 0 | E15: =E13-E14 -> 0 | F15: =F13-F14 -> 0
A17: Balance Sheet
A18: Cash
A19: Accounts Receivable | B19: =B41 -> 0 | C19: =C41 -> 0 | D19: =D41 -> 0 | E19: =E41 -> 0 | F19: =F41 -> 0
A20: Inventory | B20: ='Working Capital Schedule'!B9 -> 0 | C20: ='Working Capital Schedule'!C9 -> 0 | D20: ='Working Capital Schedule'!D9 -> 0 | E20: ='Working Capital Schedule'!E9 -> 0 | F20: ='Working Capital Schedule'!F9 -> 0
A21: PPE | B21: ='Working Capital Schedule'!B10 -> 0 | C21: ='Working Capital Schedule'!C10 -> 0 | D21: ='Working Capital Schedule'!D10 -> 0 | E21: ='Working Capital Schedule'!E10 -> 0 | F21: ='Working Capital Schedule'!F10 -> 0
A22: Total Assets | B22: ='PPE Schedule'!B9 -> 0 | C22: ='PPE Schedule'!C9 -> 0 | D22: ='PPE Schedule'!D9 -> 0 | E22: ='PPE Schedule'!E9 -> 0 | F22: ='PPE Schedule'!F9 -> 0
A23: Accounts Payable | B23: =B19+B20+B21+B22+B44 -> 0 | C23: =C19+C20+C21+C22+C44 -> 0 | D23: =D19+D20+D21+D22+D44 -> 0 | E23: =E19+E20+E21+E22+E44 -> 0 | F23: =F19+F20+F21+F22+F44 -> 0
A24: Debt | B24: ='Working Capital Schedule'!B11 -> 0 | C24: ='Working Capital Schedule'!C11 -> 0 | D24: ='Working Capital Schedule'!D11 -> 0 | E24: ='Working Capital Schedule'!E11 -> 0 | F24: ='Working Capital Schedule'!F11 -> 0
A25: Equity | B25: ='Debt Schedule'!B11 -> 0 | C25: ='Debt Schedule'!C11 -> 0 | D25: ='Debt Schedule'!D11 -> 0 | E25: ='Debt Schedule'!E11 -> 0 | F25: ='Debt Schedule'!F11 -> 0
A26: Total Liabilities + Equity | B26: ='Historical Financials'!D21+B15 -> 0 | C26: =B26+C15 -> 0 | D26: =C26+D15 -> 0 | E26: =D26+E15 -> 0 | F26: =E26+F15 -> 0
A27: Balance Check | B27: =B24+B25+B26+B45 -> 0 | C27: =C24+C25+C26+C45 -> 0 | D27: =D24+D25+D26+D45 -> 0 | E27: =E24+E25+E26+E45 -> 0 | F27: =F24+F25+F26+F45 -> 0
B28: =B23-B27 -> 0 | C28: =C23-C27 -> 0 | D28: =D23-D27 -> 0 | E28: =E23-E27 -> 0 | F28: =F23-F27 -> 0
A29: Cash Flow Statement
A30: Net Income
A31: Add: Depreciation | B31: =B15 -> 0 | C31: =C15 -> 0 | D31: =D15 -> 0 | E31: =E15 -> 0 | F31: =F15 -> 0
A32: Less: Change in NWC | B32: =B10 -> 0 | C32: =C10 -> 0 | D32: =D10 -> 0 | E32: =E10 -> 0 | F32: =F10 -> 0
A33: Cash from Operations | B33: ='Working Capital Schedule'!B13 -> 0 | C33: ='Working Capital Schedule'!C13 -> 0 | D33: ='Working Capital Schedule'!D13 -> 0 | E33: ='Working Capital Schedule'!E13 -> 0 | F33: ='Working Capital Schedule'!F13 -> 0
A34: Capex | B34: =B31+B32-B33 -> 0 | C34: =C31+C32-C33 -> 0 | D34: =D31+D32-D33 -> 0 | E34: =E31+E32-E33 -> 0 | F34: =F31+F32-F33 -> 0
A35: Cash from Investing | B35: =-'PPE Schedule'!B6 -> 0 | C35: =-'PPE Schedule'!C6 -> 0 | D35: =-'PPE Schedule'!D6 -> 0 | E35: =-'PPE Schedule'!E6 -> 0 | F35: =-'PPE Schedule'!F6 -> 0
A36: Debt Issued / (Repaid) | B36: =B35 -> 0 | C36: =C35 -> 0 | D36: =D35 -> 0 | E36: =E35 -> 0 | F36: =F35 -> 0
A37: Cash from Financing | B37: ='Debt Schedule'!B10 -> 0 | C37: ='Debt Schedule'!C10 -> 0 | D37: ='Debt Schedule'!D10 -> 0 | E37: ='Debt Schedule'!E10 -> 0 | F37: ='Debt Schedule'!F10 -> 0
A38: Net Change in Cash | B38: =B37 -> 0 | C38: =C37 -> 0 | D38: =D37 -> 0 | E38: =E37 -> 0 | F38: =F37 -> 0
A39: Beginning Cash | B39: =B34+B36+B38 -> 0 | C39: =C34+C36+C38 -> 0 | D39: =D34+D36+D38 -> 0 | E39: =E34+E36+E38 -> 0 | F39: =F34+F36+F38 -> 0
A40: Ending Cash | B40: ='Historical Financials'!D14 -> 0 | C40: =B41 -> 0 | D40: =C41 -> 0 | E40: =D41 -> 0 | F40: =E41 -> 0
B41: =B40+B39 -> 0 | C41: =C40+C39 -> 0 | D41: =D40+D39 -> 0 | E41: =E40+E39 -> 0 | F41: =F40+F39 -> 0
...

Sheet Ratio Dashboard
A1: Ratio Dashboard
A2: Scenario | B2: ='Control Panel'!B3 -> 0
A4: Metric | B4: FY2026E | C4: FY2027E | D4: FY2028E | E4: FY2029E | F4: FY2030E
A5: EBITDA Margin | B5: ='Projection Model'!B9/'Projection Model'!B5 -> 0 | C5: ='Projection Model'!C9/'Projection Model'!C5 -> 0 | D5: ='Projection Model'!D9/'Projection Model'!D5 -> 0 | E5: ='Projection Model'!E9/'Projection Model'!E5 -> 0 | F5: ='Projection Model'!F9/'Projection Model'!F5 -> 0
A6: ROE | B6: ='Projection Model'!B15/AVERAGE('Historical Financials'!D21,'Projection Model'!B26) -> 0 | C6: ='Projection Model'!C15/AVERAGE('Projection Model'!B26,'Projection Model'!C26) -> 0 | D6: ='Projection Model'!D15/AVERAGE('Projection Model'!C26,'Projection Model'!D26) -> 0 | E6: ='Projection Model'!E15/AVERAGE('Projection Model'!D26,'Projection Model'!E26) -> 0 | F6: ='Projection Model'!F15/AVERAGE('Projection Model'!E26,'Projection Model'!F26) -> 0
A7: ROCE | B7: ='Projection Model'!B11*(1-INDEX(Assumptions!$B$26:$F$26,1,1))/AVERAGE(('Historical Financials'!D21+'Historical Financials'!D20-'Historical Financials'!D14),('Projection Model'!B26+'Projection Model'!B25-'Projection Model'!B19)) -> 0 | C7: ='Projection Model'!C11*(1-INDEX(Assumptions!$B$26:$F$26,1,2))/AVERAGE(('Projection Model'!B26+'Projection Model'!B25-'Projection Model'!B19),('Projection Model'!C26+'Projection Model'!C25-'Projection Model'!C19)) -> 0 | D7: ='Projection Model'!D11*(1-INDEX(Assumptions!$B$26:$F$26,1,3))/AVERAGE(('Projection Model'!C26+'Projection Model'!C25-'Projection Model'!C19),('Projection Model'!D26+'Projection Model'!D25-'Projection Model'!D19)) -> 0 | E7: ='Projection Model'!E11*(1-INDEX(Assumptions!$B$26:$F$26,1,4))/AVERAGE(('Projection Model'!D26+'Projection Model'!D25-'Projection Model'!D19),('Projection Model'!E26+'Projection Model'!E25-'Projection Model'!E19)) -> 0 | F7: ='Projection Model'!F11*(1-INDEX(Assumptions!$B$26:$F$26,1,5))/AVERAGE(('Projection Model'!E26+'Projection Model'!E25-'Projection Model'!E19),('Projection Model'!F26+'Projection Model'!F25-'Projection Model'!F19)) -> 0
A8: Net Debt / EBITDA | B8: =('Projection Model'!B25-'Projection Model'!B19)/'Projection Model'!B9 -> 0 | C8: =('Projection Model'!C25-'Projection Model'!C19)/'Projection Model'!C9 -> 0 | D8: =('Projection Model'!D25-'Projection Model'!D19)/'Projection Model'!D9 -> 0 | E8: =('Projection Model'!E25-'Projection Model'!E19)/'Projection Model'!E9 -> 0 | F8: =('Projection Model'!F25-'Projection Model'!F19)/'Projection Model'!F9 -> 0
A9: Free Cash Flow | B9: ='Projection Model'!B34-'PPE Schedule'!B6 -> 0 | C9: ='Projection Model'!C34-'PPE Schedule'!C6 -> 0 | D9: ='Projection Model'!D34-'PPE Schedule'!D6 -> 0 | E9: ='Projection Model'!E34-'PPE Schedule'!E6 -> 0 | F9: ='Projection Model'!F34-'PPE Schedule'!F6 -> 0
